Workbook

Sheet SS1 calibration data
A1: entity_id | B1: last_changed | C1: timeValue | D1: state | F1: Cumulative Vol Added | G1: Time | H1: rowIndex | I1: VMC
A2: sensor.soil_sensor_e136_moisture | B2: 46097 | C2: =DATEVALUE(B2) + timevalue(B2) -> 46097 | D2: 3.36 | G2: ="3/16/2026 19:02:00" -> 3/16/2026 19:02:00 | H2: =match(datevalue(G2)+timevalue(G2),Table1[timeValue], 1) -> 87
A3: sensor.soil_sensor_e136_moisture | B3: 46097 | C3: =DATEVALUE(B3) + timevalue(B3) -> 46097 | D3: 3.39 | F3: 0 | G3: ="3/17/2026 12:05:00" -> 3/17/2026 12:05:00 | H3: =match(datevalue(G3)+timevalue(G3),Table1[timeValue], 1) -> 195 | I3: {=AVERAGE(INDEX(Table1[state], H2):INDEX(Table1[state], H3))} -> 6.2618349
A4: sensor.soil_sensor_e136_moisture | B4: 46097.001 | C4: =DATEVALUE(B4) + timevalue(B4) -> 46097.001 | D4: 3.36 | G4: ="3/17/2026 12:07" -> 3/17/2026 12:07 | H4: =match(datevalue(G4)+timevalue(G4),Table1[timeValue], 1) -> 195
A5: sensor.soil_sensor_e136_moisture | B5: 46097.002 | C5: =DATEVALUE(B5) + timevalue(B5) -> 46097.002 | D5: 3.39 | F5: 10 | G5: ="3/17/2026 16:00" -> 3/17/2026 16:00 | H5: =match(datevalue(G5)+timevalue(G5),Table1[timeValue], 1) -> 208 | I5: {=AVERAGE(INDEX(Table1[state], H4):INDEX(Table1[state], H5))} -> 5.5314286
A6: sensor.soil_sensor_e136_moisture | B6: 46097.002 | C6: =DATEVALUE(B6) + timevalue(B6) -> 46097.002 | D6: 3.36 | G6: ="3/17/2026 19:00" -> 3/17/2026 19:00 | H6: =match(datevalue(G6)+timevalue(G6),Table1[timeValue], 1) -> 217 | I6: {=AVERAGE(INDEX(Table1[state], H5):INDEX(Table1[state], H6))} -> 6.0488889
A7: sensor.soil_sensor_e136_moisture | B7: 46097.003 | C7: =DATEVALUE(B7) + timevalue(B7) -> 46097.003 | D7: 3.39 | F7: 20 | G7: ="3/18/2026 06:42" -> 3/18/2026 06:42 | H7: =match(datevalue(G7)+timevalue(G7),Table1[timeValue], 1) -> 341 | I7: {=AVERAGE(INDEX(Table1[state], H6):INDEX(Table1[state], H7))} -> 7.1221138
A8: sensor.soil_sensor_e136_moisture | B8: 46097.005 | C8: =DATEVALUE(B8) + timevalue(B8) -> 46097.005 | D8: 3.36 | F8: 32 | G8: ="3/19/2026 07:30" -> 3/19/2026 07:30 | H8: =match(datevalue(G8)+timevalue(G8),Table1[timeValue], 1) -> 648 | I8: {=AVERAGE(INDEX(Table1[state], H7):INDEX(Table1[state], H8))} -> 10.274132
A9: sensor.soil_sensor_e136_moisture | B9: 46097.009 | C9: =DATEVALUE(B9) + timevalue(B9) -> 46097.009 | D9: 3.39 | F9: 43 | G9: ="3/19/2026 08:48" -> 3/19/2026 08:48 | H9: =match(datevalue(G9)+timevalue(G9),Table1[timeValue], 1) -> 672 | I9: {=AVERAGE(INDEX(Table1[state], H8):INDEX(Table1[state], H9))} -> 11.9652
A10: sensor.soil_sensor_e136_moisture | B10: 46097.009 | C10: =DATEVALUE(B10) + timevalue(B10) -> 46097.009 | D10: 3.36
A11: sensor.soil_sensor_e136_moisture | B11: 46097.039 | C11: =DATEVALUE(B11) + timevalue(B11) -> 46097.039 | D11: 3.39 | F11: 32 | G11: ="3/19/2026 07:30" -> 3/19/2026 07:30 | H11: =match(datevalue(G11)+timevalue(G11),Table5[Timevalue], 1) -> 781
A12: sensor.soil_sensor_e136_moisture | B12: 46097.039 | C12: =DATEVALUE(B12) + timevalue(B12) -> 46097.039 | D12: 3.36 | F12: 43 | G12: ="3-19-2026 15:20:00" -> 3-19-2026 15:20:00 | H12: =match(datevalue(G12)+timevalue(G12),Table5[Timevalue], 1) -> 902 | I12: {=AVERAGE(INDEX(Table5[VMC], H11):INDEX(Table5[VMC], H12))} -> 12.320738
A13: sensor.soil_sensor_e136_moisture | B13: 46097.329 | C13: =DATEVALUE(B13) + timevalue(B13) -> 46097.329 | D13: 3.39 | G13: ="3/19/2026 15:40" -> 3/19/2026 15:40 | H13: =match(datevalue(G13)+timevalue(G13),Table5[Timevalue], 1) -> 907 | I13: {=AVERAGE(INDEX(Table5[VMC], H12):INDEX(Table5[VMC], H13))} -> 12.518333
A14: sensor.soil_sensor_e136_moisture | B14: 46097.341 | C14: =DATEVALUE(B14) + timevalue(B14) -> 46097.341 | D14: 3.36 | F14: 54 | G14: ="3/19/2026 16:30" -> 3/19/2026 16:30 | H14: =match(datevalue(G14)+timevalue(G14),Table5[Timevalue], 1) -> 924 | I14: {=AVERAGE(INDEX(Table5[VMC], H13):INDEX(Table5[VMC], H14))} -> 13.135
A15: sensor.soil_sensor_e136_moisture | B15: 46097.341 | C15: =DATEVALUE(B15) + timevalue(B15) -> 46097.341 | D15: 3.43
A16: sensor.soil_sensor_e136_moisture | B16: 46097.342 | C16: =DATEVALUE(B16) + timevalue(B16) -> 46097.342 | D16: 3.36
A17: sensor.soil_sensor_e136_moisture | B17: 46097.343 | C17: =DATEVALUE(B17) + timevalue(B17) -> 46097.343 | D17: 3.39 | G17: ="3/19/2026 18:21" -> 3/19/2026 18:21 | H17: =match(datevalue(G17)+timevalue(G17),'SS calibration data'!D$3:D$80, 1) -> 1
A18: sensor.soil_sensor_e136_moisture | B18: 46097.344 | C18: =DATEVALUE(B18) + timevalue(B18) -> 46097.344 | D18: 3.43 | F18: 54 | G18: ="3/20/2026 09:30" -> 3/20/2026 09:30 | H18: =match(datevalue(G18)+timevalue(G18),'SS calibration data'!D$3:D$80, 1) -> 25 | I18: {=AVERAGE(INDEX(Table2[state], H17):INDEX(Table2[state], H18))} -> 13.740417
A19: sensor.soil_sensor_e136_moisture | B19: 46097.345 | C19: =DATEVALUE(B19) + timevalue(B19) -> 46097.345 | D19: 3.39 | G19: ="3/20/2026 09:40" -> 3/20/2026 09:40 | H19: =match(datevalue(G19)+timevalue(G19),'SS calibration data'!D$3:D$80, 1) -> 25
A20: sensor.soil_sensor_e136_moisture | B20: 46097.346 | C20: =DATEVALUE(B20) + timevalue(B20) -> 46097.346 | D20: 3.36 | F20: 66 | G20: ="3/21/2026 6:30" -> 3/21/2026 6:30 | H20: =match(datevalue(G20)+timevalue(G20),'SS calibration data'!D$3:D$80, 1) -> 77 | I20: {=AVERAGE(INDEX(Table2[state], H19):INDEX(Table2[state], H20))} -> 15.396038
A21: sensor.soil_sensor_e136_moisture | B21: 46097.347 | C21: =DATEVALUE(B21) + timevalue(B21) -> 46097.347 | D21: 3.43
A22: sensor.soil_sensor_e136_moisture | B22: 46097.347 | C22: =DATEVALUE(B22) + timevalue(B22) -> 46097.347 | D22: 3.36
A23: sensor.soil_sensor_e136_moisture | B23: 46097.35 | C23: =DATEVALUE(B23) + timevalue(B23) -> 46097.35 | D23: 3.43
A24: sensor.soil_sensor_e136_moisture | B24: 46097.36 | C24: =DATEVALUE(B24) + timevalue(B24) -> 46097.36 | D24: unavailable
A25: sensor.soil_sensor_e136_moisture | B25: 46097.37 | C25: =DATEVALUE(B25) + timevalue(B25) -> 46097.37 | D25: 3.43
A26: sensor.soil_sensor_e136_moisture | B26: 46097.371 | C26: =DATEVALUE(B26) + timevalue(B26) -> 46097.371 | D26: 4.06
A27: sensor.soil_sensor_e136_moisture | B27: 46097.372 | C27: =DATEVALUE(B27) + timevalue(B27) -> 46097.372 | D27: 4.13
A28: sensor.soil_sensor_e136_moisture | B28: 46097.372 | C28: =DATEVALUE(B28) + timevalue(B28) -> 46097.372 | D28: 4.08
A29: sensor.soil_sensor_e136_moisture | B29: 46097.374 | C29: =DATEVALUE(B29) + timevalue(B29) -> 46097.374 | D29: 4.13
A30: sensor.soil_sensor_e136_moisture | B30: 46097.387 | C30: =DATEVALUE(B30) + timevalue(B30) -> 46097.387 | D30: 11.49
A31: sensor.soil_sensor_e136_moisture | B31: 46097.39 | C31: =DATEVALUE(B31) + timevalue(B31) -> 46097.39 | D31: 11.21
A32: sensor.soil_sensor_e136_moisture | B32: 46097.393 | C32: =DATEVALUE(B32) + timevalue(B32) -> 46097.393 | D32: 11.17
A33: sensor.soil_sensor_e136_moisture | B33: 46097.394 | C33: =DATEVALUE(B33) + timevalue(B33) -> 46097.394 | D33: 11.11
A34: sensor.soil_sensor_e136_moisture | B34: 46097.396 | C34: =DATEVALUE(B34) + timevalue(B34) -> 46097.396 | D34: 11.06
A35: sensor.soil_sensor_e136_moisture | B35: 46097.409 | C35: =DATEVALUE(B35) + timevalue(B35) -> 46097.409 | D35: 10.86
A36: sensor.soil_sensor_e136_moisture | B36: 46097.413 | C36: =DATEVALUE(B36) + timevalue(B36) -> 46097.413 | D36: 10.7
... A217: sensor.soil_sensor_e136_moisture | B217: 46098.785 | C217: =DATEVALUE(B217) + timevalue(B217) -> 46098.785 | D217: 6.39
A218: sensor.soil_sensor_e136_moisture | B218: 46098.79 | C218: =DATEVALUE(B218) + timevalue(B218) -> 46098.79 | D218: unavailable
A219: sensor.soil_sensor_e136_moisture | B219: 46098.792 | C219: =DATEVALUE(B219) + timevalue(B219) -> 46098.792 | D219: 6.56
A220: sensor.soil_sensor_e136_moisture | B220: 46098.823 | C220: =DATEVALUE(B220) + timevalue(B220) -> 46098.823 | D220: 7.56
...

Sheet SS calibration data
B2: entity_id | C2: state | D2: last_changed
B3: sensor.ss_e139_moisture | C3: 13.83 | D3: 46100.764
B4: sensor.ss_e139_moisture | C4: 13.77 | D4: 46100.877
B5: sensor.ss_e139_moisture | C5: 13.83 | D5: 46100.877
B6: sensor.ss_e139_moisture | C6: 13.77 | D6: 46100.892
B7: sensor.ss_e139_moisture | C7: 13.83 | D7: 46100.893
B8: sensor.ss_e139_moisture | C8: 13.77 | D8: 46100.899
B9: sensor.ss_e139_moisture | C9: 13.83 | D9: 46100.899
B10: sensor.ss_e139_moisture | C10: 13.77 | D10: 46100.906
B11: sensor.ss_e139_moisture | C11: 13.73 | D11: 46100.907
B12: sensor.ss_e139_moisture | C12: unavailable | D12: 46100.912
B13: sensor.ss_e139_moisture | C13: 13.57 | D13: 46100.921
B14: sensor.ss_e139_moisture | C14: 13.5 | D14: 46100.928
B15: sensor.ss_e139_moisture | C15: 13.57 | D15: 46100.935
B16: sensor.ss_e139_moisture | C16: 13.5 | D16: 46100.98
B17: sensor.ss_e139_moisture | C17: 13.57 | D17: 46100.987
B18: sensor.ss_e139_moisture | C18: 13.5 | D18: 46100.994
B19: sensor.ss_e139_moisture | C19: 13.57 | D19: 46101.031
B20: sensor.ss_e139_moisture | C20: 13.5 | D20: 46101.038
B21: sensor.ss_e139_moisture | C21: 14.14 | D21: 46101.17
B22: sensor.ss_e139_moisture | C22: 14.17 | D22: 46101.178
B23: sensor.ss_e139_moisture | C23: 13.57 | D23: 46101.185
B24: sensor.ss_e139_moisture | C24: 13.66 | D24: 46101.192
... B182: sensor.ss_e139_voltage | C182: 7.663 | D182: 46100.906
B183: sensor.ss_e139_voltage | C183: unavailable | D183: 46100.912
B184: sensor.ss_e139_voltage | C184: 7.681 | D184: 46100.921
B185: sensor.ss_e139_voltage | C185: 7.67 | D185: 46100.943
B186: sensor.ss_e139_voltage | C186: 7.645 | D186: 46100.965
B187: sensor.ss_e139_voltage | C187: 7.606 | D187: 46100.987
B188: sensor.ss_e139_voltage | C188: 7.599 | D188: 46101.009
B189: sensor.ss_e139_voltage | C189: 7.673 | D189: 46101.031
B190: sensor.ss_e139_voltage | C190: 7.616 | D190: 46101.053
B191: sensor.ss_e139_voltage | C191: 7.641 | D191: 46101.097
B192: sensor.ss_e139_voltage | C192: 7.656 | D192: 46101.119
B193: sensor.ss_e139_voltage | C193: 7.688 | D193: 46101.141
B194: sensor.ss_e139_voltage | C194: 7.67 | D194: 46101.163
B195: sensor.ss_e139_voltage | C195: 7.652 | D195: 46101.185
... B289: sensor.ss_e139_conductivity | C289: 456 | D289: 46100.906
B290: sensor.ss_e139_conductivity | C290: unavailable | D290: 46100.912
B291: sensor.ss_e139_conductivity | C291: 455 | D291: 46100.921
...

Sheet VMCvsVolAdded
B4: volume soil initial | C4: 900
B5: vol water initial | C5: 0.05
B9: Cumulative Vol Added (mL) | C9: VMC measured | D9: VMC soil
B10: 0 | C10: 6.2618349 | D10: =(C$4 * C$5 + B10) / (C$4 + B10) *100 -> 5
B11: 10 | C11: 5.5314286 | D11: =(C$4 * C$5 + B11) / (C$4 + B11) *100 -> 6.043956
B12: 20 | C12: 7.1221138 | D12: =(C$4 * C$5 + B12) / (C$4 + B12) *100 -> 7.0652174
B13: 32 | C13: 10.274132 | D13: =(C$4 * C$5 + B13) / (C$4 + B13) *100 -> 8.2618026
B14: 43 | C14: 11.9652 | D14: =(C$4 * C$5 + B14) / (C$4 + B14) *100 -> 9.3319194
B15: 43 | C15: 12.320738 | D15: =(C$4 * C$5 + B15) / (C$4 + B15) *100 -> 9.3319194
B16: 54 | C16: 13.135 | D16: =(C$4 * C$5 + B16) / (C$4 + B16) *100 -> 10.377358
B17: 54 | C17: 13.740417 | D17: =(C$4 * C$5 + B17) / (C$4 + B17) *100 -> 10.377358
B18: 66 | C18: 15.396038 | D18: =(C$4 * C$5 + B18) / (C$4 + B18) *100 -> 11.490683

Sheet Battery1Discharge
B2: Status: DISCHARGE ENABLED
B3: Timestamp(ms) | C3: Current(mA)
B4: 3 | C4: 92.3
B5: --- DISCHARGE CUTOFF REACHED ---
B6: Final Current: 0.00
B7: Status: DISCHARGE ENABLED
B8: Timestamp(ms) | C8: Current(mA)
B9: Status: DISCHARGE ENABLED
B10: Timestamp(ms) | C10: Current(mA) | F10: Vcutoff | G10: Icutoff (mA) | H10: Rload
B11: --- DISCHARGE CUTOFF REACHED --- | F11: 7.2 | G11: =F11/$H$11 * 1000 -> 120.53215 | H11: =1/(1/220+1/82) -> 59.735099
B12: Final Current: 0.00 | F12: 6 | G12: =F12/$H$11 * 1000 -> 100.44346
B13: Status: DISCHARGE ENABLED
B14: Timestamp(ms) | C14: Current(mA)
B15: 3 | C15: 91.1 | F15: DISCHARGE
B16: 20004 | C16: 93.1 | F16: Battery #2 | G16: h | H16: i | I16: mAh
B17: 40006 | C17: 93.2 | F17: Not logged | G17: =5 + 24 / 60 -> 5.4 | H17: 93 | I17: =G17*H17 -> 502.2
B18: 60008 | C18: 93.3
B19: 80010 | C19: 93.2 | F19: Logged | G19: Index | H19: Current | I19: mAh
B20: 100011 | C20: 93.2 | G20: 15
B21: 120012 | C21: 93.2 | G21: 760 | H21: {=AVERAGE(INDEX(C:C, G20):INDEX(C:C, G21))} -> 91.882976 | I21: {=(INDEX(B:B, G21) - INDEX(B:B, G20)) / 1000 / 3600} -> 4.1392689
B22: 140014 | C22: 93.2 | G22: 761
B23: 160016 | C23: 93.2 | G23: 869 | H23: {=AVERAGE(INDEX(C:C, G22):INDEX(C:C, G23))} -> 120.72844 | I23: {=(INDEX(B:B, G23) - INDEX(B:B, G22)) / 1000 / 3600} -> 0.60005778
B24: 180018 | C24: 93.2
B25: 200019 | C25: 93.2 | G25: capacity (mAh) | I25: =SUMPRODUCT(H20:H23, I20:I23) -> 452.77238
B26: 220021 | C26: 93.1 | G26: total capacity | I26: =sum(I25,I17) -> 954.97238
B27: 240023 | C27: 93.2 | F27: Battery #1
B28: 260025 | C28: 93.2 | F28: Logged | G28: Index | H28: Current | I28: mAh
B29: 280027 | C29: 93.1 | G29: 881
B30: 300028 | C30: 93.2 | G30: 2078 | H30: {=AVERAGE(INDEX(D:D, G29):INDEX(D:D, G30))} -> 134.41795 | I30: {=(INDEX(B:B, G30) - INDEX(B:B, G29)) / 1000 / 3600} -> 6.6509533
B31: 320030 | C31: 93.1 | G31: 2079
B32: 340032 | C32: 93.1 | G32: 2244 | H32: {=AVERAGE(INDEX(D:D, G31):INDEX(D:D, G32))} -> 127.92108 | I32: {=(INDEX(B:B, G32) - INDEX(B:B, G31)) / 1000 / 3600} -> 0.91679583
B33: 360034 | C33: 93.2
B34: 380036 | C34: 93.2 | G34: capacity (mAh) | I34: =SUMPRODUCT(H29:H32, I29:I32) -> 1011.285
B35: 400037 | C35: 93.1
B36: 420039 | C36: 93.2
B37: 440041 | C37: 93.2
B38: 460043 | C38: 93.2
B39: 480045 | C39: 93.2
B40: 500046 | C40: 93.2
B41: 520048 | C41: 93.1
...

Sheet Battery2Discharge
B3: Timestamp(ms) | C3: Voltage (V) | D3: Current(mA) | F3: 4
B4: 4 | C4: 7.89 | D4: 134.5 | F4: 1124 | G4: {=average(index(D:D,F3):index(D:D,F4))} -> 132.86887
B5: 20005 | C5: 7.88 | D5: 137.6 | G5: {=index(B:B,F3)-index(B:B,F4)} -> -22403210
B6: 40008 | C6: 7.88 | D6: 137.8 | G6: =-G4 * G5 / 3600000 -> 826.85809
B7: 60011 | C7: 7.87 | D7: 137.8
B8: 80014 | C8: 7.87 | D8: 137.8
B9: 100017 | C9: 7.87 | D9: 137.8
B10: 120019 | C10: 7.87 | D10: 137.8
B11: 140022 | C11: 7.87 | D11: 137.7
B12: 160025 | C12: 7.86 | D12: 137.7
B13: 180028 | C13: 7.86 | D13: 137.7
B14: 200031 | C14: 7.86 | D14: 137.7
B15: 220034 | C15: 7.86 | D15: 137.7
B16: 240036 | C16: 7.86 | D16: 137.7
B17: 260039 | C17: 7.86 | D17: 137.6
B18: 280042 | C18: 7.86 | D18: 137.7
... B1124: 22403214 | C1124: 7.2 | D1124: 125.7
B1125: --- SHUTDOWN: LOW VOLTAGE ---

Sheet Batt1DischargeV2
B4: Timestamp(ms) | C4: Time 1 | D4: Time 2 | E4: Voltage (V) | F4: Current(mA)
B5: 4 | D5: =if(C5<>0,C5+B$21,B5) -> 4 | E5: 8.23 | F5: 140.5
B6: 20005 | D6: =if(C6<>0,C6+B$21,B6) -> 20005 | E6: 8.2 | F6: 143.6
B7: 40008 | D7: =if(C7<>0,C7+B$21,B7) -> 40008 | E7: 8.2 | F7: 143.6
B8: 60011 | D8: =if(C8<>0,C8+B$21,B8) -> 60011 | E8: 8.18 | F8: 143.5
B9: 80014 | D9: =if(C9<>0,C9+B$21,B9) -> 80014 | E9: 8.18 | F9: 143.4
B10: 100017 | D10: =if(C10<>0,C10+B$21,B10) -> 100017 | E10: 8.17 | F10: 143.4
B11: 120019 | D11: =if(C11<>0,C11+B$21,B11) -> 120019 | E11: 8.17 | F11: 143.3
B12: 140022 | D12: =if(C12<>0,C12+B$21,B12) -> 140022 | E12: 8.16 | F12: 143.2
B13: 160025 | D13: =if(C13<>0,C13+B$21,B13) -> 160025 | E13: 8.16 | F13: 143.1
B14: 180028 | D14: =if(C14<>0,C14+B$21,B14) -> 180028 | E14: 8.15 | F14: 143
B15: 200031 | D15: =if(C15<>0,C15+B$21,B15) -> 200031 | E15: 8.14 | F15: 142.9
B16: 220034 | D16: =if(C16<>0,C16+B$21,B16) -> 220034 | E16: 8.14 | F16: 142.9
... B21: 320048 | D21: =if(C21<>0,C21+B$21,B21) -> 320048 | E21: 8.12 | F21: 142.6
C22: 4 | D22: =if(C22<>0,C22+B$21,B22) -> 320052 | E22: 8.14 | F22: 139.1
C23: 20005 | D23: =if(C23<>0,C23+B$21,B23) -> 340053 | E23: 8.12 | F23: 142.2
C24: 40008 | D24: =if(C24<>0,C24+B$21,B24) -> 360056 | E24: 8.11 | F24: 142.2
C25: 60011 | D25: =if(C25<>0,C25+B$21,B25) -> 380059 | E25: 8.11 | F25: 142.2
C26: 80014 | D26: =if(C26<>0,C26+B$21,B26) -> 400062 | E26: 8.1 | F26: 142.1
C27: 100017 | D27: =if(C27<>0,C27+B$21,B27) -> 420065 | E27: 8.1 | F27: 142.1
C28: 120019 | D28: =if(C28<>0,C28+B$21,B28) -> 440067 | E28: 8.1 | F28: 142.1
C29: 140022 | D29: =if(C29<>0,C29+B$21,B29) -> 460070 | E29: 8.1 | F29: 142.1
C30: 160025 | D30: =if(C30<>0,C30+B$21,B30) -> 480073 | E30: 8.09 | F30: 142
C31: 180028 | D31: =if(C31<>0,C31+B$21,B31) -> 500076 | E31: 8.09 | F31: 141.9
C32: 200031 | D32: =if(C32<>0,C32+B$21,B32) -> 520079 | E32: 8.09 | F32: 142
C33: 220034 | D33: =if(C33<>0,C33+B$21,B33) -> 540082 | E33: 8.09 | F33: 141.9
... C2062: 40805870 | D2062: =if(C2062<>0,C2062+B$21,B2062) -> 41125918 | E2062: 6 | F2062: 103.8
B2063: --- SHUTDOWN: LOW VOLTAGE ---

Sheet Batt2DischargeV2
G4: Batt# | H4: dischargeTime (h) | I4: avr current | J4: mAh
B5: Status: DISCHARGE ENABLED | G5: Batt2 | H5: =max(Table7[Timestamp(ms)]) / 3600 / 1000 -> 11.384971 | I5: =average(Table7[Current(mA)]) -> 132.97834 | J5: =H5*I5 -> 1513.9546
G6: Batt1 | H6: =(Batt1DischargeV2!B21 + Batt1DischargeV2!C2062)/3600/1000 -> 11.423866 | I6: =average(Batt1DischargeV2!F5:F2062) -> 134.13596 | J6: =H6*I6 -> 1532.3512
B7: Timestamp(ms) | C7: Voltage(V) | D7: Current(mA)
B8: 4 | C8: 8 | D8: 135.8
B9: 20005 | C9: 7.99 | D9: 139.6
B10: 40008 | C10: 7.99 | D10: 139.7
B11: 60011 | C11: 7.98 | D11: 139.7
B12: 80014 | C12: 7.98 | D12: 139.8
B13: 100017 | C13: 7.98 | D13: 139.6
B14: 120019 | C14: 7.97 | D14: 139.6
B15: 140022 | C15: 7.97 | D15: 139.6
B16: 160025 | C16: 7.97 | D16: 139.6
B17: 180028 | C17: 7.97 | D17: 139.5
B18: 200031 | C18: 7.97 | D18: 139.6
B19: 220034 | C19: 7.97 | D19: 139.6
... B2057: 40985897 | C2057: 6 | D2057: 103.9
B2058: --- SHUTDOWN: LOW VOLTAGE ---

Sheet voltageData
A1: entity_id | B1: state | C1: last_changed
A2: sensor.ss_e139_voltage | B2: 7.534 | C2: 2026-03-23T09:00:00.000Z | E2: Measured
A4: sensor.ss_e139_voltage | B4: 7.577 | C4: 2026-03-23T09:00:34.658Z | E4: Average | F4: Stdev | G4: Actual
A5: sensor.ss_e139_voltage | B5: 7.524 | C5: 2026-03-23T09:02:32.805Z | E5: =AVERAGE(B2:B17) -> 7.5102667 | F5: =STDEV(B2:B17) -> 0.033471665 | G5: 7.4
A6: sensor.ss_e139_voltage | B6: 7.52 | C6: 2026-03-23T09:03:32.122Z | E6: =AVERAGE(B19:B34) -> 7.2196875 | F6: =STDEV(B19:B34) -> 0.024112842 | G6: 7.2
A7: sensor.ss_e139_voltage | B7: 7.474 | C7: 2026-03-23T09:04:31.229Z | E7: =AVERAGE(B38:B63) -> 7.0141154 | F7: =STDEV(B38:B63) -> 0.030309506 | G7: 7
A8: sensor.ss_e139_voltage | B8: 7.502 | C8: 2026-03-23T09:05:30.414Z | E8: =average(B65:B89) -> 6.80088 | F8: =STDEV(B65:B89) -> 0.029480672 | G8: 6.8
A9: sensor.ss_e139_voltage | B9: 7.541 | C9: 2026-03-23T09:06:29.577Z | E9: =average(B91:B99) -> 6.5925556 | F9: =STDEV(B91:B99) -> 0.012420861 | G9: 6.6
A10: sensor.ss_e139_voltage | B10: 7.481 | C10: 2026-03-23T09:07:28.868Z | E10: =average(B101:B123) -> 6.4002609 | F10: =STDEV(B101:B123) -> 0.022571538 | G10: 6.4
A11: sensor.ss_e139_voltage | B11: 7.527 | C11: 2026-03-23T09:08:27.972Z | E11: =average(B125:B128) -> 6.193 | F11: =STDEV(B125:B128) -> 0.027676705 | G11: 6.2
A12: sensor.ss_e139_voltage | B12: 7.502 | C12: 2026-03-23T09:09:27.036Z
A13: sensor.ss_e139_voltage | B13: 7.484 | C13: 2026-03-23T09:10:39.679Z
A14: sensor.ss_e139_voltage | B14: 7.499 | C14: 2026-03-23T09:11:39.062Z
A15: sensor.ss_e139_voltage | B15: 7.556 | C15: 2026-03-23T09:12:38.115Z
A16: sensor.ss_e139_voltage | B16: 7.459 | C16: 2026-03-23T09:13:37.218Z
A17: sensor.ss_e139_voltage | B17: 7.474 | C17: 2026-03-23T09:14:36.805Z
A18: sensor.ss_e139_voltage | B18: 7.242 | C18: 2026-03-23T09:15:35.784Z
A19: sensor.ss_e139_voltage | B19: 7.199 | C19: 2026-03-23T09:16:35.174Z
A20: sensor.ss_e139_voltage | B20: 7.227 | C20: 2026-03-23T09:17:33.858Z
A21: sensor.ss_e139_voltage | B21: 7.199 | C21: 2026-03-23T09:18:33.137Z
A22: sensor.ss_e139_voltage | B22: 7.206 | C22: 2026-03-23T09:19:32.243Z
A23: sensor.ss_e139_voltage | B23: 7.252 | C23: 2026-03-23T09:20:31.523Z
... A128: sensor.ss_e139_voltage | B128: 6.171 | C128: 2026-03-23T11:32:41.038Z

Sheet soilCalibration
J2: volume soil initial | K2: 900
C3: entity_id | D3: state | E3: last_changed | F3: cumulativeVolume | G3: VMC actual | J3: vol water initial | K3: 0.09
C4: sensor.ss_e139_moisture | D4: 9.43 | E4: 2026-03-21T10:00:31.230Z | F4: 0 | G4: =(K$2 * K$3 + F4) / (K$2 + F4) *100 -> 9
C5: sensor.ss_e139_moisture | D5: 9.55 | E5: 2026-03-21T10:11:04.944Z | F5: 0 | G5: =(K$2 * K$3 + F5) / (K$2 + F5) *100 -> 9
C6: sensor.ss_e139_moisture | D6: 9.6 | E6: 2026-03-21T10:21:39.518Z | F6: 0 | G6: =(K$2 * K$3 + F6) / (K$2 + F6) *100 -> 9
C7: sensor.ss_e139_moisture | D7: 9.66 | E7: 2026-03-21T10:42:46.315Z | F7: 0 | G7: =(K$2 * K$3 + F7) / (K$2 + F7) *100 -> 9
C8: sensor.ss_e139_moisture | D8: 9.72 | E8: 2026-03-21T10:53:20.083Z | F8: 0 | G8: =(K$2 * K$3 + F8) / (K$2 + F8) *100 -> 9
C9: sensor.ss_e139_moisture | D9: 9.76 | E9: 2026-03-21T11:03:54.129Z | F9: 0 | G9: =(K$2 * K$3 + F9) / (K$2 + F9) *100 -> 9
C10: sensor.ss_e139_moisture | D10: 9.82 | E10: 2026-03-21T11:46:09.287Z | F10: 0 | G10: =(K$2 * K$3 + F10) / (K$2 + F10) *100 -> 9
C11: sensor.ss_e139_moisture | D11: 9.92 | E11: 2026-03-21T11:56:43.317Z | F11: 0 | G11: =(K$2 * K$3 + F11) / (K$2 + F11) *100 -> 9
C12: sensor.ss_e139_moisture | D12: 9.97 | E12: 2026-03-21T12:17:51.261Z | F12: 0 | G12: =(K$2 * K$3 + F12) / (K$2 + F12) *100 -> 9
C13: sensor.ss_e139_moisture | D13: 9.6 | E13: 2026-03-21T13:52:56.681Z | F13: 0 | G13: =(K$2 * K$3 + F13) / (K$2 + F13) *100 -> 9
C14: sensor.ss_e139_moisture | D14: 9.76 | E14: 2026-03-21T14:03:30.640Z | F14: 0 | G14: =(K$2 * K$3 + F14) / (K$2 + F14) *100 -> 9
C15: sensor.ss_e139_moisture | D15: 9.72 | E15: 2026-03-21T14:14:04.533Z | F15: 0 | G15: =(K$2 * K$3 + F15) / (K$2 + F15) *100 -> 9
... C170: sensor.ss_e139_moisture | D170: 15.92 | E170: 2026-03-23T11:19:51.858Z | F170: 66 | G170: =(K$2 * K$3 + F170) / (K$2 + F170) *100 -> 15.217391

Sheet CumVolumePivot
B2: cumulativeVolume | C2: AVERAGE of state | D2: MAX of state | E2: MEDIAN of state
B3: 0 | C3: 9.74875 | D3: 9.97 | E3: 9.76
B4: 11 | C4: 10.13 | D4: 10.3 | E4: 10.13
B5: 22 | C5: 10.5805 | D5: 11.06 | E5: 10.54
B6: 32 | C6: 11.873889 | D6: 12.28 | E6: 11.93
B7: 42 | C7: 13.384643 | D7: 14.03 | E7: 13.535
B8: 52 | C8: 14.688333 | D8: 15.21 | E8: 14.69
B9: 66 | C9: 15.77 | D9: 16.69 | E9: 15.71
B10: Grand Total | C10: 13.191018 | D10: 16.69 | E10: 13.66

Sheet ActualVMCPivot
B2: VMC actual | C2: AVERAGE of state | D2: MAX of state | E2: MEDIAN of state
B3: 9 | C3: 9.74875 | D3: 9.97 | E3: 9.76
B4: 10.098793 | C4: 10.13 | D4: 10.3 | E4: 10.13
B5: 11.171367 | C5: 10.5805 | D5: 11.06 | E5: 10.54
B6: 12.124464 | C6: 11.873889 | D6: 12.28 | E6: 11.93
B7: 13.057325 | C7: 13.384643 | D7: 14.03 | E7: 13.535
B8: 13.970588 | C8: 14.688333 | D8: 15.21 | E8: 14.69
B9: 15.217391 | C9: 15.77 | D9: 16.69 | E9: 15.71
B10: Grand Total | C10: 13.191018 | D10: 16.69 | E10: 13.66

Sheet plateauVMC
B3: cumulativeVolume | C3: VMC actual | D3: AVERAGE of state | E3: MAX of state | F3: MEDIAN of state | G3: plateauState
B4: 0 | C4: 9 | D4: 9.74875 | E4: 9.97 | F4: 9.76 | G4: 9.8
B5: 11 | C5: 10.098793 | D5: 10.13 | E5: 10.3 | F5: 10.13 | G5: 10.1
B6: 22 | C6: 11.171367 | D6: 10.5805 | E6: 11.06 | F6: 10.54 | G6: 10.6
B7: 32 | C7: 12.124464 | D7: 11.873889 | E7: 12.28 | F7: 11.93 | G7: 12.3
B8: 42 | C8: 13.057325 | D8: 13.384643 | E8: 14.03 | F8: 13.535 | G8: 14
B9: 52 | C9: 13.970588 | D9: 14.688333 | E9: 15.21 | F9: 14.69 | G9: 15.2
B10: 66 | C10: 15.217391 | D10: 15.77 | E10: 16.69 | F10: 15.71 | G10: 15.9
